<?xml version="1.0"?>

<robot name="dualarm" xmlns:xacro="http://www.ros.org/wiki/xacro">

  <!-- some parameters -->
  <xacro:property name="pi" value="3.141592654" />

  <!-- Import all Gazebo-customization elements, including Gazebo colors -->
  <xacro:include filename="$(find dualarm)/urdf/dualarm.gazebo.xacro" />

  <!-- Import Rviz colors -->
  <xacro:include filename="$(find dualarm)/urdf/materials.xacro" />


  <!-- World -->
  <link name="world">
  </link>

  <!-- World fixed joint-->
  <joint name="world_fixed" type="fixed">
    <origin xyz="0 0 1" rpy="0 0 0"/>
    <parent link="world"/>
    <child link="base_link"/>
  </joint>

  <!-- base_link -->
  <link
    name="base_link">
    <inertial>
      <origin
        xyz="0.0038889 0.029746 -0.075699"
        rpy="0 0 0" />
      <mass
        value="0.18539" />
      <inertia
        ixx="0.00049652"
        ixy="8.6971E-10"
        ixz="1.7643E-10"
        iyy="0.00066277"
        iyz="5.6329E-05"
        izz="0.0010875" />
    </inertial>
    <visual>
      <origin
        xyz="0 0 0"
        rpy="0 0 0" />
      <geometry>
        <mesh
          filename="package://dualarm/meshes/base_link.STL" />
      </geometry>
      <material name="grey"/>
    </visual>
    <collision>
      <origin
        xyz="0 0 0"
        rpy="0 0 0" />
      <geometry>
        <mesh
          filename="package://dualarm/meshes/base_link.STL" />
      </geometry>
    </collision>
  </link>

  <!-- Link 11 -->
  <link
    name="Link11">
    <inertial>
      <origin
        xyz="-0.00269072051291798 -0.0191705920936856 -1.21513910045223E-13"
        rpy="0 0 0" />
      <mass
        value="0.0124705129427262" />
      <inertia
        ixx="2.48875397091717E-06"
        ixy="-2.9114222346888E-07"
        ixz="-9.51641516240206E-19"
        iyy="4.55520464990268E-06"
        iyz="-8.35562268263905E-18"
        izz="5.90161236148901E-06" />
    </inertial>
    <visual>
      <origin
        xyz="0 0 0"
        rpy="0 0 0" />
      <geometry>
        <mesh
          filename="package://dualarm/meshes/Link11.STL" />
      </geometry>
      <material name="grey"/>
    </visual>
    <collision>
      <origin
        xyz="0 0 0"
        rpy="0 0 0" />
      <geometry>
        <mesh
          filename="package://dualarm/meshes/Link11.STL" />
      </geometry>
    </collision>
  </link>

  <!-- joint 11 -->
  <joint
    name="Joint11"
    type="revolute">
    <origin
      xyz="-0.061111 0.06738 -0.10422"
      rpy="1.5708 0 0" />
    <parent
      link="base_link" />
    <child
      link="Link11" />
    <axis
      xyz="0 1 0" />
    <limit velocity="6.2" effort="30" lower="${-pi}" upper="${pi}" />
  </joint>

  <!-- Transmission 11 -->
  <transmission name="tran11">
    <type>transmission_interface/SimpleTransmission</type>
    <joint name="Joint11">
      <hardwareInterface>PositionJointInterface</hardwareInterface>
    </joint>
    <actuator name="motor11">
      <hardwareInterface>PositionJointInterface</hardwareInterface>
      <mechanicalReduction>1</mechanicalReduction>
    </actuator>
  </transmission>

  <!-- Link 12 -->
  <link
    name="Link12">
    <inertial>
      <origin
        xyz="0.000212933772728602 -0.0417952294892064 0.000631634826922869"
        rpy="0 0 0" />
      <mass
        value="0.101748371406373" />
      <inertia
        ixx="0.000111914150536004"
        ixy="6.25280181032915E-13"
        ixz="5.27690890980885E-11"
        iyy="2.05143313948086E-05"
        iyz="1.53155981169772E-06"
        izz="0.000119727474259993" />
    </inertial>
    <visual>
      <origin
        xyz="0 0 0"
        rpy="0 0 0" />
      <geometry>
        <mesh
          filename="package://dualarm/meshes/Link12.STL" />
      </geometry>
      <material name="grey"/>
    </visual>
    <collision>
      <origin
        xyz="0 0 0"
        rpy="0 0 0" />
      <geometry>
        <mesh
          filename="package://dualarm/meshes/Link12.STL" />
      </geometry>
    </collision>
  </link>

  <!-- joint 12 -->
  <joint
    name="Joint12"
    type="revolute">
    <origin
      xyz="0 -0.0335 0"
      rpy="0 0 0" />
    <parent
      link="Link11" />
    <child
      link="Link12" />
    <axis
      xyz="1 0 0" />
    <limit velocity="6.2" effort="30" lower="${-pi}" upper="${pi}" />
  </joint>

  <!-- Transmission 12 -->
  <transmission name="tran12">
    <type>transmission_interface/SimpleTransmission</type>
    <joint name="Joint12">
      <hardwareInterface>PositionJointInterface</hardwareInterface>
    </joint>
    <actuator name="motor12">
      <hardwareInterface>PositionJointInterface</hardwareInterface>
      <mechanicalReduction>1</mechanicalReduction>
    </actuator>
  </transmission>

  <!-- Link 13 -->
  <link
    name="Link13">
    <inertial>
      <origin
        xyz="-0.000258356234005427 -0.0534811075287439 0.00109998454286461"
        rpy="0 0 0" />
      <mass
        value="0.0723018406954735" />
      <inertia
        ixx="5.24840463906742E-05"
        ixy="6.59201374784951E-07"
        ixz="-1.48226262014348E-07"
        iyy="1.93084109883808E-05"
        iyz="3.7637324307432E-06"
        izz="5.93005152649361E-05" />
    </inertial>
    <visual>
      <origin
        xyz="0 0 0"
        rpy="0 0 0" />
      <geometry>
        <mesh
          filename="package://dualarm/meshes/Link13.STL" />
      </geometry>
      <material name="grey"/>
    </visual>
    <collision>
      <origin
        xyz="0 0 0"
        rpy="0 0 0" />
      <geometry>
        <mesh
          filename="package://dualarm/meshes/Link13.STL" />
      </geometry>
    </collision>
  </link>

  <!-- joint 13 -->
  <joint
    name="Joint13"
    type="revolute">
    <origin
      xyz="0 -0.0835900457071312 0.00129006150228277"
      rpy="0 0 0" />
    <parent
      link="Link12" />
    <child
      link="Link13" />
    <axis
      xyz="1 0 0" />
    <limit velocity="6.2" effort="30" lower="${-pi}" upper="${pi}" />
  </joint>

  <!-- Transmission 13 -->
  <transmission name="tran13">
    <type>transmission_interface/SimpleTransmission</type>
    <joint name="Joint13">
      <hardwareInterface>PositionJointInterface</hardwareInterface>
    </joint>
    <actuator name="motor13">
      <hardwareInterface>PositionJointInterface</hardwareInterface>
      <mechanicalReduction>1</mechanicalReduction>
    </actuator>
  </transmission>

  <!-- Link 14 -->
  <link
    name="Link14">
    <inertial>
      <origin
        xyz="-0.000250000250822911 -0.00692686689003473 0.0375604021905745"
        rpy="0 0 0" />
      <mass
        value="0.00851487862558139" />
      <inertia
        ixx="6.91407797543249E-06"
        ixy="1.42108067425982E-15"
        ixz="5.91004952846371E-14"
        iyy="8.62639140242658E-06"
        iyz="-2.08331081779172E-06"
        izz="4.40145500323547E-06" />
    </inertial>
    <visual>
      <origin
        xyz="0 0 0"
        rpy="0 0 0" />
      <geometry>
        <mesh
          filename="package://dualarm/meshes/Link14.STL" />
      </geometry>
      <material name="grey"/>
    </visual>
    <collision>
      <origin
        xyz="0 0 0"
        rpy="0 0 0" />
      <geometry>
        <mesh
          filename="package://dualarm/meshes/Link14.STL" />
      </geometry>
    </collision>
  </link>

  <!-- joint 14 -->
  <joint
    name="Joint14"
    type="revolute">
    <origin
      xyz="0 -0.0719045361508551 -0.000988777522708054"
      rpy="1.5707963267949 0 0" />
    <parent
      link="Link13" />
    <child
      link="Link14" />
    <axis
      xyz="1 0 0" />
    <limit velocity="6.2" effort="30" lower="${-pi}" upper="${pi}" />
  </joint>

  <!-- Transmission 14 -->
  <transmission name="tran14">
    <type>transmission_interface/SimpleTransmission</type>
    <joint name="Joint14">
      <hardwareInterface>PositionJointInterface</hardwareInterface>
    </joint>
    <actuator name="motor14">
      <hardwareInterface>PositionJointInterface</hardwareInterface>
      <mechanicalReduction>1</mechanicalReduction>
    </actuator>
  </transmission>

  <!-- Link 21 -->
  <link
    name="Link21">
    <inertial>
      <origin
        xyz="0.00269072051291251 -0.0191705920936802 -1.75331971163928E-13"
        rpy="0 0 0" />
      <mass
        value="0.0124705129427262" />
      <inertia
        ixx="2.48875397091582E-06"
        ixy="2.91142223467643E-07"
        ixz="2.55062796241951E-18"
        iyy="4.55520464990268E-06"
        iyz="-5.85000658043222E-18"
        izz="5.90161236148765E-06" />
    </inertial>
    <visual>
      <origin
        xyz="0 0 0"
        rpy="0 0 0" />
      <geometry>
        <mesh
          filename="package://dualarm/meshes/Link21.STL" />
      </geometry>
      <material name="grey"/>
    </visual>
    <collision>
      <origin
        xyz="0 0 0"
        rpy="0 0 0" />
      <geometry>
        <mesh
          filename="package://dualarm/meshes/Link21.STL" />
      </geometry>
    </collision>
  </link>

  <!-- joint 21 -->
  <joint
    name="Joint21"
    type="revolute">
    <origin
      xyz="0.0688890331121791 0.0673797743375163 -0.104222956866293"
      rpy="1.5707963267949 0 0" />
    <parent
      link="base_link" />
    <child
      link="Link21" />
    <axis
      xyz="0 1 0" />
    <limit velocity="6.2" effort="30" lower="${-pi}" upper="${pi}" />
  </joint>

  <!-- Transmission 21 -->
  <transmission name="tran21">
    <type>transmission_interface/SimpleTransmission</type>
    <joint name="Joint21">
      <hardwareInterface>PositionJointInterface</hardwareInterface>
    </joint>
    <actuator name="motor21">
      <hardwareInterface>PositionJointInterface</hardwareInterface>
      <mechanicalReduction>1</mechanicalReduction>
    </actuator>
  </transmission>

  <!-- Link 22 -->
  <link
    name="Link22">
    <inertial>
      <origin
        xyz="-0.000212936674845565 -0.0417999999999742 1.33958492594122E-05"
        rpy="0 0 0" />
      <mass
        value="0.101748394735894" />
      <inertia
        ixx="0.000111914173347709"
        ixy="-3.74274225546969E-14"
        ixz="5.05175437048768E-11"
        iyy="2.04906999368515E-05"
        iyz="-1.89993088220696E-11"
        izz="0.00011975113683008" />
    </inertial>
    <visual>
      <origin
        xyz="0 0 0"
        rpy="0 0 0" />
      <geometry>
        <mesh
          filename="package://dualarm/meshes/Link22.STL" />
      </geometry>
      <material name="grey"/>
    </visual>
    <collision>
      <origin
        xyz="0 0 0"
        rpy="0 0 0" />
      <geometry>
        <mesh
          filename="package://dualarm/meshes/Link22.STL" />
      </geometry>
    </collision>
  </link>

  <!-- joint 22 -->
  <joint
    name="Joint22"
    type="revolute">
    <origin
      xyz="0 -0.0335000000001695 0"
      rpy="0 0 0" />
    <parent
      link="Link21" />
    <child
      link="Link22" />
    <axis
      xyz="1 0 0" />
    <limit velocity="6.2" effort="30" lower="${-pi}" upper="${pi}" />
  </joint>

  <!-- Transmission 22 -->
  <transmission name="tran22">
    <type>transmission_interface/SimpleTransmission</type>
    <joint name="Joint22">
      <hardwareInterface>PositionJointInterface</hardwareInterface>
    </joint>
    <actuator name="motor22">
      <hardwareInterface>PositionJointInterface</hardwareInterface>
      <mechanicalReduction>1</mechanicalReduction>
    </actuator>
  </transmission>

  <!-- Link 23 -->
  <link
    name="Link23">
    <inertial>
      <origin
        xyz="0.000258356011076918 -0.0534802413457883 0.00511995884963463"
        rpy="0 0 0" />
      <mass
        value="0.0723018421286062" />
      <inertia
        ixx="5.29721949031617E-05"
        ixy="-6.6483176337677E-07"
        ixz="-2.47921801899711E-08"
        iyy="1.95516873635774E-05"
        iyz="7.0500598856354E-06"
        izz="5.95453878396972E-05" />
    </inertial>
    <visual>
      <origin
        xyz="0 0 0"
        rpy="0 0 0" />
      <geometry>
        <mesh
          filename="package://dualarm/meshes/Link23.STL" />
      </geometry>
      <material name="grey"/>
    </visual>
    <collision>
      <origin
        xyz="0 0 0"
        rpy="0 0 0" />
      <geometry>
        <mesh
          filename="package://dualarm/meshes/Link23.STL" />
      </geometry>
    </collision>
  </link>

  <!-- joint 23 -->
  <joint
    name="Joint23"
    type="revolute">
    <origin
      xyz="0 -0.0835999999999738 0"
      rpy="0 0 0" />
    <parent
      link="Link22" />
    <child
      link="Link23" />
    <axis
      xyz="1 0 0" />
    <limit velocity="6.2" effort="30" lower="${-pi}" upper="${pi}" />
  </joint>

  <!-- Transmission 23 -->
  <transmission name="tran23">
    <type>transmission_interface/SimpleTransmission</type>
    <joint name="Joint23">
      <hardwareInterface>PositionJointInterface</hardwareInterface>
    </joint>
    <actuator name="motor23">
      <hardwareInterface>PositionJointInterface</hardwareInterface>
      <mechanicalReduction>1</mechanicalReduction>
    </actuator>
  </transmission>

  <!-- Link 24 -->
  <link
    name="Link24">
    <inertial>
      <origin
        xyz="9.99997491718391E-05 -0.00692686689003466 0.0375604021905746"
        rpy="0 0 0" />
      <mass
        value="0.00851487862558145" />
      <inertia
        ixx="6.91407797543258E-06"
        ixy="1.42107441737012E-15"
        ixz="5.91004796186852E-14"
        iyy="8.62639140242662E-06"
        iyz="-2.08331081779176E-06"
        izz="4.4014550032355E-06" />
    </inertial>
    <visual>
      <origin
        xyz="0 0 0"
        rpy="0 0 0" />
      <geometry>
        <mesh
          filename="package://dualarm/meshes/Link24.STL" />
      </geometry>
      <material name="grey"/>
    </visual>
    <collision>
      <origin
        xyz="0 0 0"
        rpy="0 0 0" />
      <geometry>
        <mesh
          filename="package://dualarm/meshes/Link24.STL" />
      </geometry>
    </collision>
  </link>

  <!-- joint 24 -->
  <joint
    name="Joint24"
    type="revolute">
    <origin
      xyz="0 -0.0718 0.004"
      rpy="1.5708 0 0" />
    <parent
      link="Link23" />
    <child
      link="Link24" />
    <axis
      xyz="1 0 0" />
    <limit velocity="6.2" effort="30" lower="${-pi}" upper="${pi}" />
  </joint>

  <!-- Transmission 24 -->
  <transmission name="tran24">
    <type>transmission_interface/SimpleTransmission</type>
    <joint name="Joint24">
      <hardwareInterface>PositionJointInterface</hardwareInterface>
    </joint>
    <actuator name="motor24">
      <hardwareInterface>PositionJointInterface</hardwareInterface>
      <mechanicalReduction>1</mechanicalReduction>
    </actuator>
  </transmission>


</robot>
